2024/04/13 12:18:23 - ERROR - Some error occured
Traceback (most recent call last):
  File "D:\Python Data Science STS\pythonProject\Logging_index.py", line 26, in <module>
    x = 1/0
        ~^~
ZeroDivisionError: division by zero
